#VRML_SIM R2025a utf8

EXTERNPROTO "https://raw.githubusercontent.com/cyberbotics/webots/R2025a/projects/objects/backgrounds/protos/TexturedBackground.proto"
EXTERNPROTO "https://raw.githubusercontent.com/cyberbotics/webots/R2025a/projects/objects/backgrounds/protos/TexturedBackgroundLight.proto"
EXTERNPROTO "https://raw.githubusercontent.com/cyberbotics/webots/R2025a/projects/objects/floors/protos/RectangleArena.proto"
EXTERNPROTO "https://raw.githubusercontent.com/cyberbotics/webots/R2025a/projects/appearances/protos/Asphalt.proto"
EXTERNPROTO "https://raw.githubusercontent.com/cyberbotics/webots/R2025a/projects/appearances/protos/CorrugatedPlates.proto"
EXTERNPROTO "https://raw.githubusercontent.com/cyberbotics/webots/R2025a/projects/devices/robotis/protos/RobotisLds01.proto"
EXTERNPROTO "https://raw.githubusercontent.com/cyberbotics/webots/R2025a/projects/appearances/protos/TireRubber.proto"
EXTERNPROTO "https://raw.githubusercontent.com/cyberbotics/webots/R2025a/projects/appearances/protos/Pcb.proto"
EXTERNPROTO "https://raw.githubusercontent.com/cyberbotics/webots/R2025a/projects/appearances/protos/RoughPolymer.proto"
EXTERNPROTO "https://raw.githubusercontent.com/cyberbotics/webots/R2025a/projects/appearances/protos/MattePaint.proto"
EXTERNPROTO "https://raw.githubusercontent.com/cyberbotics/webots/R2025a/projects/appearances/protos/BrushedAluminium.proto"

WorldInfo {
}
Viewpoint {
  orientation 0.03426252764642518 0.9993261588448129 0.013164628659769495 1.3145425812273603
  position -2.3756276323083307 -0.7581363925400574 10.839459606567273
}
TexturedBackground {
}
TexturedBackgroundLight {
}
RectangleArena {
  floorSize 3 3
  floorAppearance Asphalt {
  }
  wallHeight 0.8
  wallAppearance CorrugatedPlates {
  }
}
Robot {
  translation -1.1505459662512167 1.077865408706694 -0.0002474462851221118
  rotation 0.00296017310189283 -0.002276495924308159 0.9999930274464485 1.8342275329596782
  children [
    Display {
      name "map_display"
      width 166
      height 166
    }
    Pose {
      translation -0.03 0 0.153
      children [
        RobotisLds01 {
        }
      ]
    }
    DEF RIGHT_JOINT HingeJoint {
      jointParameters HingeJointParameters {
        position 13585.350704375795
        axis 0 1 0
        anchor 0 -0.08 0.033
      }
      device [
        RotationalMotor {
          name "right wheel motor"
          consumptionFactor -0.001
          maxVelocity 6.67
        }
        PositionSensor {
          name "right wheel sensor"
          resolution 0.00628
        }
      ]
      endPoint Solid {
        translation 0 -0.08 0.033
        rotation -1.161295971193883e-16 -1 1.2103754428682617e-16 0.46672574647166665
        children [
          DEF RIGHT_WHEEL Pose {
            rotation 1 0 0 -1.5708003061004252
            children [
              DEF WHEEL_SHAPE Group {
                children [
                  Shape {
                    appearance PBRAppearance {
                      baseColor 0 0 0
                      roughness 1
                      metalness 0
                    }
                    geometry Mesh {
                      url [
                        "https://raw.githubusercontent.com/cyberbotics/webots/R2025a/projects/robots/robotis/turtlebot/protos/meshes/wheel_shape.obj"
                      ]
                    }
                  }
                  Shape {
                    appearance PBRAppearance {
                      baseColor 0 0 0
                      roughness 1
                      metalness 0
                    }
                    geometry Mesh {
                      url [
                        "https://raw.githubusercontent.com/cyberbotics/webots/R2025a/projects/robots/robotis/turtlebot/protos/meshes/inner_wheel.obj"
                      ]
                    }
                  }
                  Shape {
                    appearance TireRubber {
                      textureTransform TextureTransform {
                        scale 1.7 0.76
                        translation 0 0.164
                      }
                      type "bike"
                    }
                    geometry Mesh {
                      url [
                        "https://raw.githubusercontent.com/cyberbotics/webots/R2025a/projects/robots/robotis/turtlebot/protos/meshes/tire.obj"
                      ]
                    }
                  }
                  Shape {
                    appearance PBRAppearance {
                    }
                    geometry Mesh {
                      url [
                        "https://raw.githubusercontent.com/cyberbotics/webots/R2025a/projects/robots/robotis/turtlebot/protos/meshes/wheel_support.obj"
                      ]
                    }
                  }
                ]
              }
            ]
          }
        ]
        name "right wheel"
        boundingObject Pose {
          rotation 1 0 0 -1.570796
          children [
            Cylinder {
              height 0.018
              radius 0.033
            }
          ]
        }
        physics Physics {
          density -1
          mass 0.028499
          centerOfMass [
            0 0 0
          ]
        }
        linearVelocity -1.4957908356967524e-07 3.485489940644477e-08 -7.768645950093074e-08
        angularVelocity -2.3221689901262858e-06 -1.4692471408052639e-07 -1.6774092574511008e-06
      }
    }
    DEF LEFT_JOINT HingeJoint {
      jointParameters HingeJointParameters {
        position 21325.974714184173
        axis 0 1 0
        anchor 0 0.08 0.033
      }
      device [
        RotationalMotor {
          name "left wheel motor"
          consumptionFactor -0.001
          maxVelocity 6.67
        }
        PositionSensor {
          name "left wheel sensor"
          resolution 0.00628
        }
      ]
      endPoint Solid {
        translation 0 0.08 0.033
        rotation -0.934654513249165 9.527904002307127e-07 -0.35555722586112454 3.14158840804391
        children [
          DEF RIGHT_WHEEL Pose {
            rotation 1 0 0 -1.5708003061004252
            children [
              USE WHEEL_SHAPE
            ]
          }
        ]
        name "left wheel"
        boundingObject Pose {
          rotation 1 0 0 -1.570796
          children [
            Cylinder {
              height 0.018
              radius 0.033
            }
          ]
        }
        physics Physics {
          density -1
          mass 0.028499
          centerOfMass [
            0 0 0
          ]
        }
        linearVelocity -2.2811616052953832e-07 3.260618856270924e-07 -5.175157571908468e-09
        angularVelocity -2.3413469050821424e-06 -1.5209683691296986e-07 -1.6774094841273346e-06
      }
    }
    DEF CASTER_JOINT BallJoint {
      jointParameters BallJointParameters {
        position -5242.843166619778
        anchor -0.081 0 0.004
      }
      endPoint Solid {
        translation -0.08105971136247914 -6.0038493254310765e-05 0.004110240125718848
        rotation 0.16003659058946315 -0.9606980445348657 0.22682053897164076 -0.8267669480404978
        children [
          Shape {
            appearance PBRAppearance {
            }
            geometry DEF CASTER_SPHERE Sphere {
              radius 0.004
              subdivision 2
            }
          }
        ]
        boundingObject USE CASTER_SPHERE
        physics Physics {
        }
        linearVelocity -1.6093888780837155e-05 -2.749846467976523e-05 1.6578514955774362e-07
        angularVelocity 0.006771089452249943 -0.004207403320377671 -0.36377480753351404
      }
    }
    DEF BODY Pose {
      translation 0 0 0.01
      children [
        DEF MOTORS Shape {
          appearance PBRAppearance {
            baseColor 0 0 0
            roughness 0.8
            metalness 0
          }
          geometry Mesh {
            url [
              "https://raw.githubusercontent.com/cyberbotics/webots/R2025a/projects/robots/robotis/turtlebot/protos/meshes/motors.obj"
            ]
          }
        }
        DEF CARDS Shape {
          appearance Pcb {
          }
          geometry Mesh {
            url [
              "https://raw.githubusercontent.com/cyberbotics/webots/R2025a/projects/robots/robotis/turtlebot/protos/meshes/cards.obj"
            ]
          }
        }
        DEF HOLDERS Shape {
          appearance DEF MAIN_APP RoughPolymer {
            baseColor 0 0 0
            textureTransform TextureTransform {
              scale 3 3
            }
          }
          geometry Mesh {
            url [
              "https://raw.githubusercontent.com/cyberbotics/webots/R2025a/projects/robots/robotis/turtlebot/protos/meshes/holders.obj"
            ]
          }
        }
        DEF BODY_FLOOR_0 Shape {
          appearance USE MAIN_APP
          geometry Mesh {
            url [
              "https://raw.githubusercontent.com/cyberbotics/webots/R2025a/projects/robots/robotis/turtlebot/protos/meshes/body_floor.obj"
            ]
          }
        }
        DEF BODY_FLOOR_1 Pose {
          translation 0 0 0.0376
          children [
            USE BODY_FLOOR_0
          ]
        }
        DEF BODY_FLOOR_2 Pose {
          translation 0 0 0.085
          children [
            USE BODY_FLOOR_0
          ]
        }
        DEF BODY_FLOOR_3 Pose {
          translation 0 0 0.1325
          children [
            USE BODY_FLOOR_0
          ]
        }
        DEF BATTERY Shape {
          appearance MattePaint {
            baseColor 0.054902 0.121569 0.356863
          }
          geometry Mesh {
            url [
              "https://raw.githubusercontent.com/cyberbotics/webots/R2025a/projects/robots/robotis/turtlebot/protos/meshes/battery.obj"
            ]
          }
        }
        DEF SCREWS Shape {
          appearance PBRAppearance {
          }
          geometry Mesh {
            url [
              "https://raw.githubusercontent.com/cyberbotics/webots/R2025a/projects/robots/robotis/turtlebot/protos/meshes/screws.obj"
            ]
          }
        }
        DEF BARS Shape {
          appearance BrushedAluminium {
            textureTransform TextureTransform {
              scale 3 2
            }
          }
          geometry Mesh {
            url [
              "https://raw.githubusercontent.com/cyberbotics/webots/R2025a/projects/robots/robotis/turtlebot/protos/meshes/bars.obj"
            ]
          }
        }
      ]
    }
    Accelerometer {
      translation -0.032 0 0.078
    }
    Gyro {
      translation -0.032 0 0.078
    }
    Compass {
      translation -0.032 0 0.078
    }
  ]
  name "TurtleBot3Burger"
  boundingObject Group {
    children [
      Pose {
        translation -0.032 0 0.08
        children [
          Box {
            size 0.097 0.137 0.1425
          }
        ]
      }
      Pose {
        translation -0.032 0 0.08
        children [
          Box {
            size 0.135 0.095 0.143
          }
        ]
      }
    ]
  }
  physics Physics {
    density -1
    mass 0.825735
    centerOfMass [
      -0.035 0 0.03
    ]
  }
  controller "turtlebot3_path_follower"
  controllerArgs [
    ""
  ]
  supervisor TRUE
  linearVelocity -2.338273593131119e-07 2.2452338178521022e-07 3.361843189717974e-08
  angularVelocity -2.322194659109252e-06 -1.4750120117780665e-07 -1.6773900184521636e-06
}
Solid {
  translation 0.391084 0.332741 0.1
  rotation 0.5773509358560258 -0.577349935856137 0.577349935856137 -2.094395307179586
  children [
    Shape {
      appearance PBRAppearance {
        baseColor 0.5 0.5 0.5
        roughness 0.8
      }
      geometry Box {
        size 0.1 0.2 1
      }
    }
  ]
  name "wall_1"
  boundingObject Box {
    size 0.1 0.2 1
  }
}
Solid {
  translation -0.147966 1.01722 0.5
  children [
    Shape {
      appearance PBRAppearance {
        baseColor 0.5 0.5 0.5
        roughness 0.8
      }
      geometry Box {
        size 0.1 0.2 1
      }
    }
  ]
  name "wall_2"
  boundingObject Box {
    size 0.1 0.2 1
  }
}
Solid {
  translation 0.259692 -0.861265 0.1
  children [
    Shape {
      appearance PBRAppearance {
        baseColor 0.5 0.5 0.5
        roughness 0.8
      }
      geometry Box {
        size 0.1 0.2 0.2
      }
    }
  ]
  name "wall_3"
  boundingObject Box {
    size 0.1 0.2 0.2
  }
}
Solid {
  translation -0.23629 -1.39294 0.1
  children [
    Shape {
      appearance PBRAppearance {
        baseColor 0.5 0.5 0.5
        roughness 0.8
      }
      geometry Box {
        size 0.1 0.2 0.2
      }
    }
  ]
  name "wall_3(1)"
  boundingObject Box {
    size 0.1 0.2 0.2
  }
}
Solid {
  translation 0.875615 -1.13203 0.1
  children [
    Shape {
      appearance PBRAppearance {
        baseColor 0.5 0.5 0.5
        roughness 0.8
      }
      geometry Box {
        size 0.1 0.2 0.2
      }
    }
  ]
  name "wall_3(2)"
  boundingObject Box {
    size 0.1 0.2 0.2
  }
}
Solid {
  translation 0.923789 -0.431245 0.1
  children [
    Shape {
      appearance PBRAppearance {
        baseColor 0.5 0.5 0.5
        roughness 0.8
      }
      geometry Box {
        size 0.1 0.2 0.2
      }
    }
  ]
  name "wall_3(3)"
  boundingObject Box {
    size 0.1 0.2 0.2
  }
}
Solid {
  translation 0.284267 -0.171343 0.1
  rotation 1 0 0 4.692820414042842e-06
  children [
    Shape {
      appearance PBRAppearance {
        baseColor 0.5 0.5 0.5
        roughness 0.8
      }
      geometry Cylinder {
        height 0.2
        radius 0.1
      }
    }
  ]
  name "Column_1"
  boundingObject Cylinder {
    height 0.2
    radius 0.1
  }
}
Solid {
  translation 0.951855 1.03477 0.1
  rotation 1 0 0 4.692820414042842e-06
  children [
    Shape {
      appearance PBRAppearance {
        baseColor 0.5 0.5 0.5
        roughness 0.8
      }
      geometry Cylinder {
        height 0.2
        radius 0.1
      }
    }
  ]
  name "Column_1(3)"
  boundingObject Cylinder {
    height 0.2
    radius 0.1
  }
}
Solid {
  translation 0.488552 0.73692 0.1
  rotation 1 0 0 4.692820414042842e-06
  children [
    Shape {
      appearance PBRAppearance {
        baseColor 0.5 0.5 0.5
        roughness 0.8
      }
      geometry Cylinder {
        height 0.2
        radius 0.1
      }
    }
  ]
  name "Column_1(4)"
  boundingObject Cylinder {
    height 0.2
    radius 0.1
  }
}
Solid {
  translation -0.72931 -0.832518 0.1
  rotation 1 0 0 4.692820414042842e-06
  children [
    Shape {
      appearance PBRAppearance {
        baseColor 0.5 0.5 0.5
        roughness 0.8
      }
      geometry Cylinder {
        height 0.2
        radius 0.1
      }
    }
  ]
  name "Column_1(1)"
  boundingObject Cylinder {
    height 0.2
    radius 0.1
  }
}
Solid {
  translation -0.743488 0.560166 0.1
  rotation 1 0 0 4.692820414042842e-06
  children [
    Shape {
      appearance PBRAppearance {
        baseColor 0.5 0.5 0.5
        roughness 0.8
      }
      geometry Cylinder {
        height 0.2
        radius 0.1
      }
    }
  ]
  name "Column_1(2)"
  boundingObject Cylinder {
    height 0.2
    radius 0.1
  }
}
